Workbook

Sheet Cover
C4: NAV Model
C5: Net Asset Value Model - Range Resources Corp. (NYSE:RRC)
C7: Theo Pham
C8: Laszlo MacCallum-von Hahn
C17: Public and Non-Confidential
C21: Last Updated | F21: 45994
C23: Company Inputs
C24: Company Name | F24: Range Resources Corperation
C25: Ticker | F25: NYSE: RRC
C26: Pricing Date | F26: =F21 -> 45994
C27: Currency | F27: USD
C31: Legend
C32: Black = Text / Intraworksheet Formulas
C33: Blue = Inputs
C34: Green = Links Between Worksheets

Sheet Inputs & Assumptions
D2: =Cover!C5 -> Net Asset Value Model - Range Resources Corp. (NYSE:RRC)
D3: Inputs & Assumptions
D5: Currently Running Commodity Price case: | H5: {=_xlfn.IFS(L37 = 1,"Street", L37=2,"Bear",L37=3,"Base",L37=4,"Bull")} -> Street
B8: 1. | C8: Inputs & Assumptions
C10: a. | D10: Investment Timeline
D12: Valuation Date
D13: Valuation Date | G13: =Cover!F21 -> 45994
C16: a. | D16: Company Inputs
H19: Units
D21: Company Name | H21: Name | K21: =Cover!F24 -> Range Resources Corperation
D22: Ticker Symbol | H22: BBG | L22: RRC US
D24: Current Share price | H24: $ | L24: 39.89
D25: FD Shares Outstanding | H25: mm | L25: 239.03
D26: Market Cap. | H26: mm $ | L26: =L24*L25 -> 9534.9067
D28: Historical Beta | H28: 5y | L28: =Comps!T3 -> 0.98369845
D30: Credit Profile
D31: Pre-tax cost of debt (Kd) | H31: % | L31: 0.0547
V32: =NAV!N36 -> 0.24943221
D33: Other
D34: Effective Tax Rate | H34: % | L34: =NAV!AU29 -> 0.25
D35: Bbl to Mcfe converstion | L35: 6
D36: Estimated realised NGL premium | L36: 1.63
D37: Commodity Price case | L37: =NAV!AU28 -> 1
D40: Discount Rate (WACC) | H40: % | L40: ='Cost of Capital'!G81 -> 0.083972982
C44: c. | D44: Market Data | J44: sources
D46: Required Returns | F46: units
D47: Risk-Free Rate of Return (Rf) | F47: % | G47: 0.04 | J47: fred: 2025.11.25
F48: x
D49: Equity Risk Premium (Rm-Rf) | F49: % | G49: 0.0576 | J49: Aswath Damodaran, U.S. ERP (TTM) as of November 1 2025
C52: d. | D52: Production and Drilling assumptions
D55: Proportion of production | H55: Units
D57: Share of production
E58: Natural Gas | H58: % | L58: 0.685
E59: Natural Gas Liguids (NGL) | H59: % | L59: 0.2986
E60: Oil | H60: % | L60: 0.0164
D63: Proved Developped Reserves | H63: Units
D65: Net PD Reserves | H65: Mmcfe | L65: 11930793
D66: PDP Daily production (Current) | H66: Mmcfe/d | L66: 2227.8
D67: Proved production decline rate | H67: % | L67: 0.05
D68: Estimated Reserve Life
...

Sheet Cost of Capital
C2: =Cover!C5 -> Net Asset Value Model - Range Resources Corp. (NYSE:RRC)
C3: Commodity Price Assumptions
C5: Currently Running Commodity Price case: | G5: {=_xlfn.IFS('Inputs & Assumptions'!L37= 1,"Street", 'Inputs & Assumptions'!L37=2,"Bear",'Inputs & Assumptions'!L37=3,"Base",'Inputs & Assumptions'!L37=4,"Bull")} -> Street
B8: x | C8: 1. | D8: Energy Transfer Cost of Capital
C10: x | D10: a. Key Assumptions
D12: WACC Inputs | G12: units
D14: Equity:
D15: Risk-Free Rate of Return (Rf) | G15: % | H15: 0.04
G16: x
D17: Equity Risk Premium (Rm-Rf) | G17: % | H17: 0.0576
D19: Debt:
D20: Pretax Cost of Debt (Kd) | G20: % | H20: 0.0547
D22: Market Capitalization | G22: mm dollars | H22: 9326.9506
D24: Net Debt | G24: th dollars | H24: 1393.4
D26: Effective Tax rate | G26: % | H26: 0.25
D28: Company
D29: Historical Beta | G29: x | H29: 0.88
C32: x | D32: b. Beta Calculation
D36: Comps Beta
D37: Name | E37: Ticker | F37: 5 Year Beta | G37: Debt | H37: % Debt | I37: Equity Value | J37: % Equity | K37: Tax Rate | L37: Unlevered Beta
D38: APA CORP | E38: APA US | F38: 1.1581892 | G38: 4219.0001 | H38: 0.32372837 | I38: 8813.5309 | J38: 0.67627163 | K38: 0.25 | L38: 0.85222267
D39: COMSTOCK RESOURCES INC | E39: CRK US | F39: 1.1035831 | G39: 3183.927 | H39: 0.29571931 | I39: 7582.7931 | J39: 0.70428069 | K39: 0.25 | L39: 0.83928007
D40: PERMIAN RESOURCES CORP | E40: PR US | F40: 1.1599289 | G40: 3577.2119 | H40: 0.23068878 | I40: 11929.446 | J40: 0.76931122 | K40: 0.25 | L40: 0.9469596
D41: CNX RESOURCES CORP | E41: CNX US | F41: 0.80980969 | G41: 2773.748 | H41: 0.3495524 | I41: 5161.3941 | J41: 0.6504476 | K41: 0.25 | L41: 0.57717719
D42: COTERRA ENERGY INC | E42: CTRA US | F42: 0.78887898 | G42: 4019.0001 | H42: 0.16665588 | I42: 20096.56 | J42: 0.83334412 | K42: 0.25 | L42: 0.68598866
D43: DEVON ENERGY CORP | E43: DVN US | F43: 1.0494801 | G43: 7271.0001 | H43: 0.24092117 | I43: 22908.996 | J43: 0.75907883 | K43: 0.25 | L43: 0.84769505
D44: EXPAND ENERGY CORP | E44: EXE US | F44: 0.83211299 | G44: 4522.9998 | H44: 0.13742859 | I44: 28388.637 | J44: 0.86257141 | K44: 0.25 | L44: 0.74329435
D45: EQT CORP | E45: EQT US | F45: 0.93071324 | G45: 7982.0861 | H45: 0.17824489 | I45: 36799.484 | J45: 0.82175511 | K45: 0.25 | L45: 0.80048913
D46: DIAMONDBACK ENERGY INC | E46: FANG US | F46: 0.97279572 | G46: 16083 | H46: 0.27290357 | I46: 42849.906 | J46: 0.72709643 | K46: 0.25 | L46: 0.75910705
D47: CONOCOPHILLIPS | E47: COP US | F47: 0.84169963 | G47: 17226 | H47: 0.13782938 | I47: 107754.61 | J47: 0.86217062 | K47: 0.25 | L47: 0.75158636
D49: Median: | F49: 0.95175448 | G49: 4370.9999 | H49: 0.23580497 | I49: 21502.778 | J49: 0.76419503 | K49: 0.25 | L49: 0.77979809
D51: Range Unlevered Beta | E51: RRC US | F51: 0.98369845 | G51: 1372.913 | H51: 0.13055138 | I51: 9143.353 | J51: 0.86944862 | K51: 0.25 | L51: 0.8841314
D54: Range - Relevered Beta
D55: Calculated Using: | E55: Ticker | F55: Unlevered Beta (Comps) | G55: Debt | H55: % Debt | I55: Equity Value | J55: % Equity | K55: Tax Rate | L55: Levered Beta
D56: Range Unlevered Beta | E56: RRC US | F56: 0.77979809 | G56: 1372.913 | H56: 0.13055138 | I56: 9143.353 | J56: 0.86944862 | K56: 0.25 | L56: 0.86761557
D57: "Optimal" Capital Structure: | F57: 0.77979809 | G57: 2479.7879 | H57: 0.23580497 | I57: 8036.4782 | J57: 0.76419503 | K57: 0.25 | L57: 0.96026276
C59: x | D59: c. Detailed WACC Calculation
D62: At Historical | I62: At Current Capital Structure | N62: At Optimal Capital Structure
D63: Equity | I63: Equity | N63: Equity
D64: Equity Risk | G64: 0.0576 | I64: Equity Risk | L64: 0.0576 | N64: Equity Risk | Q64: 0.0576
...

Sheet Comps
A1: Name | B1: Ticker | C1: Price:D-1 | D1: Mkt Cap (USD) | E1: Net Debt LF | F1: BEst EV | G1: EV/BE Sales Curr Yr | H1: EV/Next Yr Est Sales | I1: BEst Curr EV/BEst EBITDA:1FY | J1: BEst Curr EV/BEst EBITDA:1BF | K1: BEst P/E:1BF | L1: BEst P/E:1FY | M1: Net Debt to EBITDA LF | N1: BEst EBITDA:2024 | O1: BEst EBITDA:1FY | P1: BEst EBITDA:1BF | Q1: BEst NI:2024 | R1: BEst NI:1FY | S1: BEst NI:1BF | T1: Beta:Y-5 | V1: Leverage
A2: Median | B2: 0 | C2: 37.419998 | D2: 20096.56 | E2: 4219.0001 | F2: 23555.338 | G2: 3.2102293 | H2: 3.0315848 | I2: 6.3968049 | J2: 5.3704974 | K2: 12.687823 | L2: 13.43663 | M2: 1.074857 | N2: 3457.2001 | O2: 4911.1111 | P2: 5167.8376 | Q2: 1177.43 | R2: 1370.48 | S2: 1934.2434 | T2: 0.97279572 | V2: =E2/(E2+D2) -> 0.17351029
A3: RANGE RESOURCES CORP | B3: RRC US | C3: 37.799999 | D3: 9143.353 | E3: 1372.913 | F3: 10304.535 | G3: 3.5189112 | H3: 3.1327547 | I3: 7.4439277 | J3: 6.4139877 | K3: 10.717072 | L3: 13.43663 | M3: 1.2075059 | N3: 1184.7 | O3: 1391.7308 | P3: 1615.1849 | Q3: 535.58301 | R3: 688.174 | S3: 851.41547 | T3: 0.98369845 | V3: =E3/(E3+D3) -> 0.13055138
A4: APA CORP | B4: APA US | C4: 24.08 | D4: 8813.5309 | E4: 4219.0001 | F4: 13605.174 | G4: 1.6395862 | H4: 1.8072388 | I4: 2.6529707 | J4: 2.920124 | K4: 8.3853064 | L4: 6.9374651 | M4: 0.78771502 | N4: 5522.8001 | O4: 5173.2692 | P4: 4700.0374 | Q4: 1398.27 | R4: 1292.071 | S4: 995.61793 | T4: 1.1581892 | V4: =E4/(E4+D4) -> 0.32372837
A5: COMSTOCK RESOURCES INC | B5: CRK US | C5: 25.139999 | D5: 7582.7931 | E5: 3183.927 | F5: 10689.339 | G5: 5.7971591 | H5: 4.9395569 | I5: 9.9944429 | J5: 8.1798603 | K5: 28.06714 | L5: 50.23301 | M5: 3.2204919 | N5: 850.56301 | O5: 1095.1765 | P5: 1338.2756 | Q5: -112.381 | R5: 153.133 | S5: 279.59193 | T5: 1.1035831 | V5: =E5/(E5+D5) -> 0.29571931
A6: PERMIAN RESOURCES CORP | B6: PR US | C6: 14.11 | D6: 11929.446 | E6: 3577.2119 | F6: 16346.771 | G6: 2.9406542 | H6: 2.8874576 | I6: 3.9705116 | J6: 4.0490057 | K6: 11.787467 | L6: 11.31786 | M6: 0.98033798 | N6: 3684.8901 | O6: 3869.1429 | P6: 3794.1448 | Q6: 1177.43 | R6: 1045.591 | S6: 973.33612 | T6: 1.1599289 | V6: =E6/(E6+D6) -> 0.23068878
A7: CNX RESOURCES CORP | B7: CNX US | C7: 37.419998 | D7: 5161.3941 | E7: 2773.748 | F7: 7760.283 | G7: 3.9256161 | H7: 3.9112915 | I7: 6.3968049 | J7: 6.1403669 | K7: 15.209184 | L7: 17.439636 | M7: 2.794297 | N7: 996.81798 | O7: 1213.8125 | P7: 1264.4991 | Q7: 236 | R7: 361.5 | S7: 393.34101 | T7: 0.80980969 | V7: =E7/(E7+D7) -> 0.3495524
A8: COTERRA ENERGY INC | B8: CTRA US | C8: 25.84 | D8: 20096.56 | E8: 4019.0001 | F8: 23555.338 | G8: 3.2102293 | H8: 3.0315848 | I8: 5.0298763 | J8: 4.6302422 | K8: 10.244236 | L8: 11.674038 | M8: 0.91403198 | N8: 3406.4399 | O8: 4757.2857 | P8: 5167.8376 | Q8: 1200.15 | R8: 1705.261 | S8: 1934.2434 | T8: 0.78887898 | V8: =E8/(E8+D8) -> 0.16665588
A9: DEVON ENERGY CORP | B9: DVN US | C9: 35.82 | D9: 22908.996 | E9: 7271.0001 | F9: 29793.746 | G9: 1.9584351 | H9: 2.0764168 | I9: 4.0523317 | J9: 4.1338427 | K9: 8.9505181 | L9: 9.0508055 | M9: 0.936261 | N9: 7538.5201 | O9: 7447.5625 | P9: 7300.7295 | Q9: 2961.5401 | R9: 2558.7 | S9: 2506.8279 | T9: 1.0494801 | V9: =E9/(E9+D9) -> 0.24092117
A10: EXPAND ENERGY CORP | B10: EXE US | C10: 116.01 | D10: 28388.637 | E10: 4522.9998 | F10: 32503.406 | G10: 2.8689381 | H10: 2.7397825 | I10: 6.6758086 | J10: 5.3704974 | K10: 12.687823 | L10: 20.022678 | M10: 1.074857 | N10: 2095.9601 | O10: 4911.1111 | P10: 6104.629 | Q10: 207.28701 | R10: 1370.48 | S10: 2231.9713 | T10: 0.83211299 | V10: =E10/(E10+D10) -> 0.13742859
A11: EQT CORP | B11: EQT US | C11: 56.759998 | D11: 36799.484 | E11: 7982.0861 | F11: 48078.365 | G11: 5.8055244 | H11: 5.0631977 | I11: 8.9587366 | J11: 7.2329186 | K11: 13.360011 | L11: 20.263643 | M11: 1.433593 | N11: 3457.2001 | O11: 5404.8077 | P11: 6694.278 | Q11: 679.43501 | R11: 1832.87 | S11: 2705.9081 | T11: 0.93071324 | V11: =E11/(E11+D11) -> 0.17824489
A12: DIAMONDBACK ENERGY INC | B12: FANG US | C12: 147.02 | D12: 42849.906 | E12: 16083 | F12: 63622.073 | G12: 4.4680884 | H12: 4.6305387 | I12: 6.5048021 | J12: 6.6696185 | K12: 12.712326 | L12: 11.510044 | M12: 1.552713 | N12: 7363.4002 | O12: 10066.241 | P12: 9817.5177 | Q12: 3303.6301 | R12: 3793.185 | S12: 3339.102 | T12: 0.97279572 | V12: =E12/(E12+D12) -> 0.27290357
A13: CONOCOPHILLIPS | B13: COP US | C13: 86.620003 | D13: 107754.61 | E13: 17226 | F13: 124785.18 | G13: 2.0860243 | H13: 2.2769625 | I13: 4.9012484 | J13: 5.1277621 | K13: 13.842911 | L13: 13.454714 | M13: 0.717152 | N13: 24906.199 | O13: 25499.75 | P13: 24373.455 | Q13: 9220.2895 | R13: 8152.643 | S13: 7437.4093 | T13: 0.84169963 | V13: =E13/(E13+D13) -> 0.13782938
J15: =AVERAGE(J3:J13) -> 5.5334751

Sheet Commodity Price Assumptions
G2: =Cover!C5 -> Net Asset Value Model - Range Resources Corp. (NYSE:RRC)
G3: Commodity Price Assumptions | O3: 2025 | P3: 2026 | Q3: =P3+1 -> 2027 | R3: =Q3+1 -> 2028 | S3: =R3+1 -> 2029
G5: Currently Running Commodity Price case: | K5: {=_xlfn.IFS('Inputs & Assumptions'!L37= 1,"Street", 'Inputs & Assumptions'!L37=2,"Bear",'Inputs & Assumptions'!L37=3,"Base",'Inputs & Assumptions'!L37=4,"Bull")} -> Street
B8: 1. | C8: Natural Gas Price Assumptions
F10: Natural Gas prices | H10: ='Inputs & Assumptions'!L37 -> 1 | I10: {=_xlfn.IFS(H10= 1,"Street", H10=2,"Bear",H10=3,"Base",H10=4,"Bull")} -> Street | O10: =OFFSET(O12,$H10,0) -> 3.5 | P10: =OFFSET(P12,$H10,0) -> 3.84 | Q10: =OFFSET(Q12,$H10,0) -> 3.85 | R10: =OFFSET(R12,$H10,0) -> 3.81 | S10: =OFFSET(S12,$H10,0) -> 3.84
H12: unit
F13: Street | H13: $/Mcfe | O13: =O15 -> 3.5 | P13: =P15 -> 3.84 | Q13: =Q15 -> 3.85 | R13: =R15 -> 3.81 | S13: =S15 -> 3.84
F14: Bear | H14: $/Mcfe | O14: =O15-U14 -> 2.67 | P14: =P15-V14 -> 2.67 | Q14: =Q15-W14 -> 2.67 | R14: =R15-X14 -> 2.7 | S14: =S15-Y14 -> 2.75 | U14: 0.83 | V14: 1.17 | W14: 1.18 | X14: 1.11 | Y14: 1.09
F15: Base | H15: $/Mcfe | O15: =3.5 -> 3.5 | P15: =O15+0.34 -> 3.84 | Q15: =P15+0.01 -> 3.85 | R15: =Q15-0.04 -> 3.81 | S15: =NAV!AU39 -> 3.84
F16: Bull | H16: $/Mcfe | O16: =O15+0.2 -> 3.7 | P16: =P15+0.02 -> 3.86 | Q16: =Q15+0.22 -> 4.07 | R16: =R15+0.34 -> 4.15 | S16: =S15+0.56 -> 4.4
B20: 2. | C20: Oil Price Assumprions
F23: Oil Prices | H23: ='Inputs & Assumptions'!L37 -> 1 | I23: {=_xlfn.IFS(H23= 1,"Street", H23=2,"Bear",H23=3,"Base",H23=4,"Bull")} -> Street | O23: =OFFSET(O25,$H23,0) -> 64.7428 | P23: =OFFSET(P25,$H23,0) -> 58.7556 | Q23: =OFFSET(Q25,$H23,0) -> 63.66 | R23: =OFFSET(R25,$H23,0) -> 67.5392 | S23: =OFFSET(S25,$H23,0) -> 69.1789
H25: unit
F26: Street | H26: $/Bbl | O26: =O28 -> 64.7428 | P26: =P28 -> 58.7556 | Q26: =Q28 -> 63.66 | R26: =R28 -> 67.5392 | S26: =S28 -> 69.1789
F27: Bear | H27: $/Bbl | O27: =O28+W27 -> 63.89 | P27: =P28+X27 -> 54.0056 | Q27: =Q28+Y27 -> 58.91 | R27: =R28+Z27 -> 62.45 | S27: =S28+AA27 -> 66.122 | W27: -0.8528 | X27: -4.75 | Y27: -4.75 | Z27: -5.0892 | AA27: -3.0569
F28: Base | H28: $/Bbl | O28: 64.7428 | P28: =O28+X28 -> 58.7556 | Q28: =P28+Y28 -> 63.66 | R28: =Q28+Z28 -> 67.5392 | S28: =R28+AA28 -> 69.1789 | X28: -5.9872 | Y28: 4.9044 | Z28: 3.8792 | AA28: 1.6397
F29: Bull | H29: $/Bbl | O29: =O28+W29 -> 67.862 | P29: =P28+X29 -> 63.7 | Q29: =Q28+Y29 -> 67.67 | R29: =R28+Z29 -> 72.702 | S29: =S28+AA29 -> 71.422 | W29: 3.1192 | X29: 4.9444 | Y29: 4.01 | Z29: 5.1628 | AA29: 2.2431
B33: 3. | C33: NGL Price assumptions
C35: a. | D35: Natural Gasoline Price forecast
F38: Nat. Gasoline Prices | H38: ='Inputs & Assumptions'!L37 -> 1 | I38: {=_xlfn.IFS(H38= 1,"Street", H38=2,"Bear",H38=3,"Base",H38=4,"Bull")} -> Street | K38: Weight: | L38: 0.08 | O38: =OFFSET(O40,$H38,0) -> 650.5433 | P38: =OFFSET(P40,$H38,0) -> 623.1 | Q38: =OFFSET(Q40,$H38,0) -> 643.96 | R38: =OFFSET(R40,$H38,0) -> 661.19 | S38: =OFFSET(S40,$H38,0) -> 679.35
H40: unit
F41: Street | H41: $/metric Tonne | O41: =O43 -> 650.5433 | P41: =P43 -> 623.1 | Q41: =Q43 -> 643.96 | R41: =R43 -> 661.19 | S41: =S43 -> 679.35
F42: Bear | H42: $/metric Tonne | O42: =O43-20 -> 630.5433 | P42: =P43-20 -> 603.1 | Q42: =Q43-20 -> 623.96 | R42: =R43-20 -> 641.19 | S42: =S43-20 -> 659.35
F43: Base | H43: $/metric Tonne | O43: 650.5433 | P43: 623.1 | Q43: 643.96 | R43: 661.19 | S43: 679.35
F44: Bull | H44: $/metric Tonne | O44: =O43+20 -> 670.5433 | P44: =P43+20 -> 643.1 | Q44: =Q43+20 -> 663.96 | R44: =R43+20 -> 681.19 | S44: =S43+20 -> 699.35
F47: Nat. Gasoline Prices | H47: ='Inputs & Assumptions'!L37 -> 1 | I47: {=_xlfn.IFS(H47= 1,"Street", H47=2,"Bear",H47=3,"Base",H47=4,"Bull")} -> Street | O47: =OFFSET(O49,$H47,0) -> 56.081319 | P47: =OFFSET(P49,$H47,0) -> 53.715517 | Q47: =OFFSET(Q49,$H47,0) -> 55.513793 | R47: =OFFSET(R49,$H47,0) -> 56.999138 | S47: =OFFSET(S49,$H47,0) -> 58.564655
H49: unit
F50: Street | H50: $/Bbl | O50: =O52 -> 56.081319 | P50: =P52 -> 53.715517 | Q50: =Q52 -> 55.513793 | R50: =R52 -> 56.999138 | S50: =S52 -> 58.564655
F51: Bear | H51: $/Bbl | O51: =O52-2 -> 54.081319 | P51: =P52-2 -> 51.715517 | Q51: =Q52-2 -> 53.513793 | R51: =R52-2 -> 54.999138 | S51: =S52-2 -> 56.564655
F52: Base | H52: $/Bbl | O52: =O43/11.6*(1+NAV!AU49) -> 56.081319 | P52: =O52+U52 -> 53.715517 | Q52: =P52+V52 -> 55.513793 | R52: =Q52+W52 -> 56.999138 | S52: =R52+X52 -> 58.564655 | U52: -2.3658017 | V52: 1.7982759 | W52: 1.4853448 | X52: 1.5655172
F53: Bull | H53: $/Bbl | O53: =O52+2 -> 58.081319 | P53: =P52+2 -> 55.715517 | Q53: =Q52+2 -> 57.513793 | R53: =R52+2 -> 58.999138 | S53: =S52+2 -> 60.564655
C56: b. | D56: Propane Price forecast
F59: Propane Price Forecast | H59: ='Inputs & Assumptions'!L37 -> 1 | I59: {=_xlfn.IFS(H59= 1,"Street", H59=2,"Bear",H59=3,"Base",H59=4,"Bull")} -> Street | K59: Weight: | L59: 0.15 | O59: =OFFSET(O61,$H59,0) -> 0.61542 | P59: =OFFSET(P61,$H59,0) -> 0.62001667 | Q59: =OFFSET(Q61,$H59,0) -> 0.6146525 | R59: =OFFSET(R61,$H59,0) -> 0.62072917 | S59: =OFFSET(S61,$H59,0) -> 0.60604167
H61: unit
F62: Street | H62: $/Gal | O62: =O64 -> 0.61542 | P62: =P64 -> 0.62001667 | Q62: =Q64 -> 0.6146525 | R62: =R64 -> 0.62072917 | S62: =S64 -> 0.60604167
F63: Bear | H63: $/Gal | O63: =O64-0.03 -> 0.58542 | P63: =P64-0.03 -> 0.59001667 | Q63: =Q64-0.03 -> 0.5846525 | R63: =R64-0.03 -> 0.59072917 | S63: =S64-0.03 -> 0.57604167
F64: Base | H64: $/Gal | O64: 0.61542 | P64: 0.62001667 | Q64: 0.6146525 | R64: 0.62072917 | S64: 0.60604167
F65: Bull | H65: $/Gal | O65: =O64+0.03 -> 0.64542 | P65: =P64+0.03 -> 0.65001667 | Q65: =Q64+0.03 -> 0.6446525 | R65: =R64+0.03 -> 0.65072917 | S65: =S64+0.03 -> 0.63604167
F68: Propane Price Forecast | H68: ='Inputs & Assumptions'!L37 -> 1 | I68: {=_xlfn.IFS(H68= 1,"Street", H68=2,"Bear",H68=3,"Base",H68=4,"Bull")} -> Street | O68: =OFFSET(O70,$H68,0) -> 25.84764 | P68: =OFFSET(P70,$H68,0) -> 26.0407 | Q68: =OFFSET(Q70,$H68,0) -> 25.815405 | R68: =OFFSET(R70,$H68,0) -> 26.070625 | S68: =OFFSET(S70,$H68,0) -> 25.45375
H70: unit
...

Sheet PD Reserves
D2: =Cover!C5 -> Net Asset Value Model - Range Resources Corp. (NYSE:RRC)
D3: PD Reserves
D5: Currently Running Commodity Price case: | H5: {=_xlfn.IFS('Inputs & Assumptions'!L37= 1,"Street", 'Inputs & Assumptions'!L37=2,"Bear",'Inputs & Assumptions'!L37=3,"Base",'Inputs & Assumptions'!L37=4,"Bull")} -> Street
F10: Proved Developed Reserves - Production Schedule | K10: FY 2024 | L10: FY 2025 | M10: FY 2026 | N10: FY 2027 | O10: FY 2028 | P10: FY 2029 | Q10: FY 2030 | R10: FY 2031 | S10: FY 2032 | T10: FY 2033 | U10: FY 2034 | V10: FY 2035 | W10: FY 2036 | X10: FY 2037 | Y10: FY 2038 | Z10: FY 2039 | AA10: FY 2040 | AB10: FY 2041 | AC10: FY 2042 | AD10: FY 2043 | AE10: FY 2044 | AF10: FY 2045 | AG10: FY 2046 | AH10: FY 2047 | AI10: FY 2048 | AJ10: FY 2049 | AK10: FY 2050 | AL10: FY 2051 | AM10: FY 2052 | AN10: FY 2053 | AO10: FY 2054
G12: Days | K12: - | L12: 365 | M12: 365 | N12: 365 | O12: 366 | P12: 365 | Q12: 365 | R12: 365 | S12: 366 | T12: 365 | U12: 365 | V12: 365 | W12: 366 | X12: 365 | Y12: 365 | Z12: 365 | AA12: 366 | AB12: 365 | AC12: 365 | AD12: 365 | AE12: 366 | AF12: 365 | AG12: 365 | AH12: 365 | AI12: 366 | AJ12: 365 | AK12: 365 | AL12: 365 | AM12: 366 | AN12: 365 | AO12: 365
G13: Begninning reserves | K13: - | L13: ='Inputs & Assumptions'!$L$65 -> 11930793 | M13: =L16 -> 11158303 | N13: =M16 -> 10424438 | O13: =N16 -> 9727266.3 | P13: =O16 -> 9063138.4 | Q13: =P16 -> 8433940.8 | R13: =Q16 -> 7836203 | S13: =R16 -> 7268352.1 | T13: =S16 -> 6727415.8 | ... AO13: =AN16 -> 0
G14: Daily Production | K14: ='Inputs & Assumptions'!L66 -> 2227.8 | L14: =K14*(1-'Inputs & Assumptions'!$L$67) -> 2116.41 | M14: =L14*(1-'Inputs & Assumptions'!$L$67) -> 2010.5895 | N14: =M14*(1-'Inputs & Assumptions'!$L$67) -> 1910.06 | O14: =N14*(1-'Inputs & Assumptions'!$L$67) -> 1814.557 | P14: =O14*(1-'Inputs & Assumptions'!$L$67) -> 1723.8292 | Q14: =P14*(1-'Inputs & Assumptions'!$L$67) -> 1637.6377 | R14: =Q14*(1-'Inputs & Assumptions'!$L$67) -> 1555.7558 | S14: =R14*(1-'Inputs & Assumptions'!$L$67) -> 1477.968 | ... AO14: =AN14*(1-'Inputs & Assumptions'!$L$67) -> 478.17224
G15: Annual Production | K15: - | L15: =MIN(L14*L12,L13) -> 772489.65 | M15: =MIN(M14*M12,M13) -> 733865.17 | N15: =MIN(N14*N12,N13) -> 697171.91 | O15: =MIN(O14*O12,O13) -> 664127.87 | P15: =MIN(P14*P12,P13) -> 629197.65 | Q15: =MIN(Q14*Q12,Q13) -> 597737.77 | R15: =MIN(R14*R12,R13) -> 567850.88 | S15: =MIN(S14*S12,S13) -> 540936.3 | ... AO15: =MIN(AO14*AO12,AO13) -> 0
G16: Ending Reserves | K16: - | L16: =L13-L15 -> 11158303 | M16: =M13-M15 -> 10424438 | N16: =N13-N15 -> 9727266.3 | O16: =O13-O15 -> 9063138.4 | P16: =P13-P15 -> 8433940.8 | Q16: =Q13-Q15 -> 7836203 | R16: =R13-R15 -> 7268352.1 | S16: =S13-S15 -> 6727415.8 | ... AO16: =AO13-AO15 -> 0
F20: Proved Developed Reserves - Cash Flows
B22: 1. | C22: Net Production
G24: Total Mmcfe | L24: =L15 -> 772489.65 | M24: =M15 -> 733865.17 | N24: =N15 -> 697171.91 | O24: =O15 -> 664127.87 | P24: =P15 -> 629197.65 | Q24: =Q15 -> 597737.77 | R24: =R15 -> 567850.88 | S24: =S15 -> 540936.3 | ... AO24: =AO15 -> 0
G25: Gas Mmcf | L25: =L24*'Inputs & Assumptions'!$L$58 -> 529155.41 | M25: =M24*'Inputs & Assumptions'!$L$58 -> 502697.64 | N25: =N24*'Inputs & Assumptions'!$L$58 -> 477562.76 | O25: =O24*'Inputs & Assumptions'!$L$58 -> 454927.59 | P25: =P24*'Inputs & Assumptions'!$L$58 -> 431000.39 | Q25: =Q24*'Inputs & Assumptions'!$L$58 -> 409450.37 | R25: =R24*'Inputs & Assumptions'!$L$58 -> 388977.85 | S25: =S24*'Inputs & Assumptions'!$L$58 -> 370541.37 | ... AO25: =AO24*'Inputs & Assumptions'!$L$58 -> 0
G26: NGL MBbl | L26: =L24*'Inputs & Assumptions'!$L$59/'Inputs & Assumptions'!$L$35 -> 38444.235 | M26: =M24*'Inputs & Assumptions'!$L$59/'Inputs & Assumptions'!$L$35 -> 36522.023 | N26: =N24*'Inputs & Assumptions'!$L$59/'Inputs & Assumptions'!$L$35 -> 34695.922 | O26: =O24*'Inputs & Assumptions'!$L$59/'Inputs & Assumptions'!$L$35 -> 33051.43 | P26: =P24*'Inputs & Assumptions'!$L$59/'Inputs & Assumptions'!$L$35 -> 31313.07 | Q26: =Q24*'Inputs & Assumptions'!$L$59/'Inputs & Assumptions'!$L$35 -> 29747.416 | R26: =R24*'Inputs & Assumptions'!$L$59/'Inputs & Assumptions'!$L$35 -> 28260.045 | S26: =S24*'Inputs & Assumptions'!$L$59/'Inputs & Assumptions'!$L$35 -> 26920.597 | ... AO26: =AO24*'Inputs & Assumptions'!$L$59/'Inputs & Assumptions'!$L$35 -> 0
G27: Oil MBbl | L27: =L24*'Inputs & Assumptions'!$L$60/'Inputs & Assumptions'!$L$35 -> 2111.4717 | M27: =M24*'Inputs & Assumptions'!$L$60/'Inputs & Assumptions'!$L$35 -> 2005.8981 | N27: =N24*'Inputs & Assumptions'!$L$60/'Inputs & Assumptions'!$L$35 -> 1905.6032 | O27: =O24*'Inputs & Assumptions'!$L$60/'Inputs & Assumptions'!$L$35 -> 1815.2828 | P27: =P24*'Inputs & Assumptions'!$L$60/'Inputs & Assumptions'!$L$35 -> 1719.8069 | Q27: =Q24*'Inputs & Assumptions'!$L$60/'Inputs & Assumptions'!$L$35 -> 1633.8166 | R27: =R24*'Inputs & Assumptions'!$L$60/'Inputs & Assumptions'!$L$35 -> 1552.1257 | S27: =S24*'Inputs & Assumptions'!$L$60/'Inputs & Assumptions'!$L$35 -> 1478.5592 | ... AO27: =AO24*'Inputs & Assumptions'!$L$60/'Inputs & Assumptions'!$L$35 -> 0
B29: 2. | C29: Revenue
C31: a. | D31: Natural Gas Revenue
G33: $ MM | L33: =L25*'Commodity Price Assumptions'!O10/1000 -> 1852.0439 | M33: =M25*'Commodity Price Assumptions'!P10/1000 -> 1930.3589 | N33: =N25*'Commodity Price Assumptions'!Q10/1000 -> 1838.6166 | O33: =O25*'Commodity Price Assumptions'!R10/1000 -> 1733.2741 | P33: =P25*'Commodity Price Assumptions'!$S$10/1000 -> 1655.0415 | Q33: =Q25*'Commodity Price Assumptions'!$S$10/1000 -> 1572.2894 | R33: =R25*'Commodity Price Assumptions'!$S$10/1000 -> 1493.6749 | S33: =S25*'Commodity Price Assumptions'!$S$10/1000 -> 1422.8788 | T33: =T25*'Commodity Price Assumptions'!$S$10/1000 -> 1348.0416 | U33: =U25*'Commodity Price Assumptions'!$S$10/1000 -> 1280.6396 | V33: =V25*'Commodity Price Assumptions'!$S$10/1000 -> 1216.6076 | W33: =W25*'Commodity Price Assumptions'!$S$10/1000 -> 1158.9437 | ... AO33: =AO25*'Commodity Price Assumptions'!$S$10/1000 -> 0
C35: b. | D35: NGL Revenue
G37: $ MM | L37: =L26*'Commodity Price Assumptions'!O122/1000*'Inputs & Assumptions'!$L$36 -> 1370.96 | M37: =M26*'Commodity Price Assumptions'!P122/1000*'Inputs & Assumptions'!$L$36 -> 1265.9392 | N37: =N26*'Commodity Price Assumptions'!Q122/1000*'Inputs & Assumptions'!$L$36 -> 1252.6174 | O37: =O26*'Commodity Price Assumptions'!R122/1000*'Inputs & Assumptions'!$L$36 -> 1157.9227 | P37: =P26*'Commodity Price Assumptions'!$S$122/1000*'Inputs & Assumptions'!$L$36 -> 1074.5509 | Q37: =Q26*'Commodity Price Assumptions'!$S$122/1000*'Inputs & Assumptions'!$L$36 -> 1020.8233 | R37: =R26*'Commodity Price Assumptions'!$S$122/1000*'Inputs & Assumptions'!$L$36 -> 969.78215 | S37: =S26*'Commodity Price Assumptions'!$S$122/1000*'Inputs & Assumptions'!$L$36 -> 923.81713 | T37: =T26*'Commodity Price Assumptions'!$S$122/1000*'Inputs & Assumptions'!$L$36 -> 875.22839 | U37: =U26*'Commodity Price Assumptions'!$S$122/1000*'Inputs & Assumptions'!$L$36 -> 831.46697 | V37: =V26*'Commodity Price Assumptions'!$S$122/1000*'Inputs & Assumptions'!$L$36 -> 789.89362 | W37: =W26*'Commodity Price Assumptions'!$S$122/1000*'Inputs & Assumptions'!$L$36 -> 752.45483 | ... AO37: =AO26*'Commodity Price Assumptions'!$S$122/1000*'Inputs & Assumptions'!$L$36 -> 0
C39: c. | D39: Oil Revenue
G41: $ MM | L41: =L27*'Commodity Price Assumptions'!O23/1000 -> 136.70259 | M41: =M27*'Commodity Price Assumptions'!P23/1000 -> 117.85775 | N41: =N27*'Commodity Price Assumptions'!Q23/1000 -> 121.3107 | O41: =O27*'Commodity Price Assumptions'!R23/1000 -> 122.60275 | P41: =P27*'Commodity Price Assumptions'!$S$23/1000 -> 118.97435 | Q41: =Q27*'Commodity Price Assumptions'!$S$23/1000 -> 113.02563 | R41: =R27*'Commodity Price Assumptions'!$S$23/1000 -> 107.37435 | S41: =S27*'Commodity Price Assumptions'!$S$23/1000 -> 102.2851 | T41: =T27*'Commodity Price Assumptions'!$S$23/1000 -> 96.905352 | U41: =U27*'Commodity Price Assumptions'!$S$23/1000 -> 92.060084 | V41: =V27*'Commodity Price Assumptions'!$S$23/1000 -> 87.45708 | W41: =W27*'Commodity Price Assumptions'!$S$23/1000 -> 83.311854 | ... AO41: =AO27*'Commodity Price Assumptions'!$S$23/1000 -> 0
B44: 3. | C44: Expenses
C46: a. | D46: Production Taxes
E48: Per Unit Price | G48: $/Mcfe | L48: ='Inputs & Assumptions'!$L$73 -> 0.04 | M48: ='Inputs & Assumptions'!$L$73 -> 0.04 | N48: ='Inputs & Assumptions'!$L$73 -> 0.04 | O48: ='Inputs & Assumptions'!$L$73 -> 0.04 | P48: ='Inputs & Assumptions'!$L$73 -> 0.04 | Q48: ='Inputs & Assumptions'!$L$73 -> 0.04 | R48: ='Inputs & Assumptions'!$L$73 -> 0.04 | S48: ='Inputs & Assumptions'!$L$73 -> 0.04 | ... AO48: ='Inputs & Assumptions'!$L$73 -> 0.04
E50: Total | G50: $MM | L50: =L48*L24/1000 -> 30.899586 | M50: =M48*M24/1000 -> 29.354607 | N50: =N48*N24/1000 -> 27.886876 | O50: =O48*O24/1000 -> 26.565115 | P50: =P48*P24/1000 -> 25.167906 | Q50: =Q48*Q24/1000 -> 23.909511 | R50: =R48*R24/1000 -> 22.714035 | S50: =S48*S24/1000 -> 21.637452 | ... AO50: =AO48*AO24/1000 -> 0
C52: b. | D52: Lease Operating Expense (LOE)
E54: Per Unit Price | G54: $/Mcfe | L54: ='Inputs & Assumptions'!$L$74 -> 0.14 | M54: ='Inputs & Assumptions'!$L$74 -> 0.14 | N54: ='Inputs & Assumptions'!$L$74 -> 0.14 | O54: ='Inputs & Assumptions'!$L$74 -> 0.14 | P54: ='Inputs & Assumptions'!$L$74 -> 0.14 | Q54: ='Inputs & Assumptions'!$L$74 -> 0.14 | R54: ='Inputs & Assumptions'!$L$74 -> 0.14 | S54: ='Inputs & Assumptions'!$L$74 -> 0.14 | ... AO54: ='Inputs & Assumptions'!$L$74 -> 0.14
E56: Total | G56: $MM | L56: =L54*L24/1000 -> 108.14855 | M56: =M54*M24/1000 -> 102.74112 | N56: =N54*N24/1000 -> 97.604067 | O56: =O54*O24/1000 -> 92.977902 | P56: =P54*P24/1000 -> 88.087671 | Q56: =Q54*Q24/1000 -> 83.683287 | R56: =R54*R24/1000 -> 79.499123 | S56: =S54*S24/1000 -> 75.731082 | ... AO56: =AO54*AO24/1000 -> 0
C58: c. | D58: Transport Expense
E60: Per Unit Price | G60: $/Mcfe | L60: ='Inputs & Assumptions'!$L$75 -> 1.642 | M60: ='Inputs & Assumptions'!$L$75 -> 1.642 | N60: ='Inputs & Assumptions'!$L$75 -> 1.642 | O60: ='Inputs & Assumptions'!$L$75 -> 1.642 | P60: ='Inputs & Assumptions'!$L$75 -> 1.642 | Q60: ='Inputs & Assumptions'!$L$75 -> 1.642 | R60: ='Inputs & Assumptions'!$L$75 -> 1.642 | S60: ='Inputs & Assumptions'!$L$75 -> 1.642 | ... AO60: ='Inputs & Assumptions'!$L$75 -> 1.642
E62: Total | G62: $MM | L62: =L60*L24/1000 -> 1268.428 | M62: =M60*M24/1000 -> 1205.0066 | N62: =N60*N24/1000 -> 1144.7563 | O62: =O60*O24/1000 -> 1090.498 | P62: =P60*P24/1000 -> 1033.1425 | Q62: =Q60*Q24/1000 -> 981.48541 | R62: =R60*R24/1000 -> 932.41114 | S62: =S60*S24/1000 -> 888.21741 | ... AO62: =AO60*AO24/1000 -> 0
B65: 4. | C65: Cash Flows
E67: Cash Flow from Operations | L67: =SUM(L33:L41)-L62 -> 2091.2785 | M67: =SUM(M33:M41)-M62 -> 2109.1493 | N67: =SUM(N33:N41)-N62 -> 2067.7884 | O67: =SUM(O33:O41)-O62 -> 1923.3016 | P67: =SUM(P33:P41)-P62 -> 1815.4242 | Q67: =SUM(Q33:Q41)-Q62 -> 1724.653 | R67: =SUM(R33:R41)-R62 -> 1638.4203 | S67: =SUM(S33:S41)-S62 -> 1560.7637 | ... AO67: =SUM(AO33:AO41)-AO62 -> 0
E69: CapEx | L69: =(L24/$L$13)*'Inputs & Assumptions'!$L$78 -> 54.868804 | M69: =(M24/$L$13)*'Inputs & Assumptions'!$L$78 -> 52.125363 | N69: =(N24/$L$13)*'Inputs & Assumptions'!$L$78 -> 49.519095 | O69: =(O24/$L$13)*'Inputs & Assumptions'!$L$78 -> 47.172026 | P69: =(P24/$L$13)*'Inputs & Assumptions'!$L$78 -> 44.690983 | Q69: =(Q24/$L$13)*'Inputs & Assumptions'!$L$78 -> 42.456434 | R69: =(R24/$L$13)*'Inputs & Assumptions'!$L$78 -> 40.333613 | S69: =(S24/$L$13)*'Inputs & Assumptions'!$L$78 -> 38.42191 | ... AO69: =(AO24/$L$13)*'Inputs & Assumptions'!$L$78 -> 0
E71: FCF | L71: =L67-L69 -> 2036.4097 | M71: =M67-M69 -> 2057.024 | N71: =N67-N69 -> 2018.2693 | O71: =O67-O69 -> 1876.1296 | P71: =P67-P69 -> 1770.7332 | Q71: =Q67-Q69 -> 1682.1965 | R71: =R67-R69 -> 1598.0867 | S71: =S67-S69 -> 1522.3418 | ... AO71: =AO67-AO69 -> 0
B73: 5. | C73: Discounted Cash Flow
E75: Year | L75: 1 | M75: 2 | N75: 3 | O75: 4 | P75: 5 | Q75: 6 | R75: 7 | S75: 8 | T75: 9 | U75: 10 | V75: 11 | W75: 12 | X75: 13 | Y75: 14 | Z75: 15 | AA75: 16 | AB75: 17 | AC75: 18 | AD75: 19 | AE75: 20 | AF75: 21 | AG75: 22 | AH75: 23 | AI75: 24 | AJ75: 25 | AK75: 26 | AL75: 27 | AM75: 28 | AN75: 29 | AO75: 30
E77: Discount Factor | L77: =1/((1+'Inputs & Assumptions'!$L$40)^('PD Reserves'!L75-1)) -> 1 | M77: =1/((1+'Inputs & Assumptions'!$L$40)^('PD Reserves'!M75-1)) -> 0.92253222 | N77: =1/((1+'Inputs & Assumptions'!$L$40)^('PD Reserves'!N75-1)) -> 0.85106569 | O77: =1/((1+'Inputs & Assumptions'!$L$40)^('PD Reserves'!O75-1)) -> 0.78513552 | P77: =1/((1+'Inputs & Assumptions'!$L$40)^('PD Reserves'!P75-1)) -> 0.72431282 | Q77: =1/((1+'Inputs & Assumptions'!$L$40)^('PD Reserves'!Q75-1)) -> 0.66820191 | R77: =1/((1+'Inputs & Assumptions'!$L$40)^('PD Reserves'!R75-1)) -> 0.61643779 | S77: =1/((1+'Inputs & Assumptions'!$L$40)^('PD Reserves'!S75-1)) -> 0.56868372 | ... AO77: =1/((1+'Inputs & Assumptions'!$L$40)^('PD Reserves'!AO75-1)) -> 0.096486095
E79: DCF | G79: $MM | L79: =L71*L77 -> 2036.4097 | M79: =M71*M77 -> 1897.6709 | N79: =N71*N77 -> 1717.6798 | O79: =O71*O77 -> 1473.016 | P79: =P71*P77 -> 1282.5647 | Q79: =Q71*Q77 -> 1124.0469 | R79: =R71*R77 -> 985.12103 | S79: =S71*S77 -> 865.73098 | ... AO79: =AO71*AO77 -> 0
...

Sheet PUD Reserves
D2: =Cover!C5 -> Net Asset Value Model - Range Resources Corp. (NYSE:RRC)
D3: PUD Reserves
D5: Currently Running Commodity Price case: | H5: {=_xlfn.IFS('Inputs & Assumptions'!L37= 1,"Street", 'Inputs & Assumptions'!L37=2,"Bear",'Inputs & Assumptions'!L37=3,"Base",'Inputs & Assumptions'!L37=4,"Bull")} -> Street
F10: Proved Undeveloped Reserves - Production Schedule | L10: FY 2025 | M10: FY 2026 | N10: FY 2027 | O10: FY 2028 | P10: FY 2029 | Q10: FY 2030 | R10: FY 2031 | S10: FY 2032 | T10: FY 2033 | U10: FY 2034 | V10: FY 2035 | W10: FY 2036 | X10: FY 2037 | Y10: FY 2038 | Z10: FY 2039 | AA10: FY 2040 | AB10: FY 2041 | AC10: FY 2042 | AD10: FY 2043 | AE10: FY 2044 | AF10: FY 2045 | AG10: FY 2046 | AH10: FY 2047 | AI10: FY 2048 | AJ10: FY 2049 | AK10: FY 2050 | AL10: FY 2051 | AM10: FY 2052 | AN10: FY 2053 | AO10: FY 2054 | AP10: FY 2055 | AQ10: FY 2056 | AR10: FY 2057 | AS10: FY 2058 | AT10: FY 2059 | AU10: FY 2060 | AV10: FY 2061 | AW10: FY 2062 | AX10: FY 2063 | AY10: FY 2064
G11: Period | J11: Total | L11: 1 | M11: 2 | N11: 3 | O11: 4 | P11: 5 | Q11: 6 | R11: 7 | S11: 8 | T11: 9 | U11: 10 | V11: 11 | W11: 12 | X11: 13 | Y11: 14 | Z11: 15 | AA11: 16 | AB11: 17 | AC11: 18 | AD11: 19 | AE11: 20 | AF11: 21 | AG11: 22 | AH11: 23 | AI11: 24 | AJ11: 25 | AK11: 26 | AL11: 27 | AM11: 28 | AN11: 29 | AO11: 30 | AP11: 31 | AQ11: 32 | AR11: 33 | AS11: 34 | AT11: 35 | AU11: 35 | AV11: 35 | AW11: 35 | AX11: 35 | AY11: 35
G12: Days | L12: 365 | M12: 365 | N12: 365 | O12: 366 | P12: 365 | Q12: 365 | R12: 365 | S12: 366 | T12: 365 | U12: 365 | V12: 365 | W12: 366 | X12: 365 | Y12: 365 | Z12: 365 | AA12: 366 | AB12: 365 | AC12: 365 | AD12: 365 | AE12: 366 | AF12: 365 | AG12: 365 | AH12: 365 | AI12: 366 | AJ12: 365 | AK12: 365 | AL12: 365 | AM12: 366 | AN12: 365 | AO12: 365 | AP12: 365 | AQ12: 366 | AR12: 365 | AS12: 365 | AT12: 365 | AU12: 366 | AV12: 365 | AW12: 365 | AX12: 365 | AY12: 366
H13: Gas MMcf | J13: =SUM(L13:AO13) -> 10275 | L13: =L16*'Inputs & Assumptions'!$L$58 -> 1284.375 | M13: =M16*'Inputs & Assumptions'!$L$58 -> 822 | N13: =N16*'Inputs & Assumptions'!$L$58 -> 690.48 | O13: =O16*'Inputs & Assumptions'!$L$58 -> 600.7176 | P13: =P16*'Inputs & Assumptions'!$L$58 -> 540.64584 | Q13: =Q16*'Inputs & Assumptions'!$L$58 -> 486.58126 | R13: =R16*'Inputs & Assumptions'!$L$58 -> 442.78894 | S13: =S16*'Inputs & Assumptions'!$L$58 -> 407.36583 | ... AY13: =AY16*'Inputs & Assumptions'!$L$58 -> 0
H14: NGL MBbl | J14: =SUM(L14:AO14) -> 746.5 | L14: =L16*'Inputs & Assumptions'!$L$59/'Inputs & Assumptions'!$L$35 -> 93.3125 | M14: =M16*'Inputs & Assumptions'!$L$59/'Inputs & Assumptions'!$L$35 -> 59.72 | N14: =N16*'Inputs & Assumptions'!$L$59/'Inputs & Assumptions'!$L$35 -> 50.1648 | O14: =O16*'Inputs & Assumptions'!$L$59/'Inputs & Assumptions'!$L$35 -> 43.643376 | P14: =P16*'Inputs & Assumptions'!$L$59/'Inputs & Assumptions'!$L$35 -> 39.279038 | Q14: =Q16*'Inputs & Assumptions'!$L$59/'Inputs & Assumptions'!$L$35 -> 35.351135 | R14: =R16*'Inputs & Assumptions'!$L$59/'Inputs & Assumptions'!$L$35 -> 32.169532 | S14: =S16*'Inputs & Assumptions'!$L$59/'Inputs & Assumptions'!$L$35 -> 29.59597 | ... AY14: =AY16*'Inputs & Assumptions'!$L$59/'Inputs & Assumptions'!$L$35 -> 0
H15: Oil MBbl | J15: =SUM(L15:AO15) -> 41 | L15: =L16*'Inputs & Assumptions'!$L$60/'Inputs & Assumptions'!$L$35 -> 5.125 | M15: =M16*'Inputs & Assumptions'!$L$60/'Inputs & Assumptions'!$L$35 -> 3.28 | N15: =N16*'Inputs & Assumptions'!$L$60/'Inputs & Assumptions'!$L$35 -> 2.7552 | O15: =O16*'Inputs & Assumptions'!$L$60/'Inputs & Assumptions'!$L$35 -> 2.397024 | P15: =P16*'Inputs & Assumptions'!$L$60/'Inputs & Assumptions'!$L$35 -> 2.1573216 | Q15: =Q16*'Inputs & Assumptions'!$L$60/'Inputs & Assumptions'!$L$35 -> 1.9415894 | R15: =R16*'Inputs & Assumptions'!$L$60/'Inputs & Assumptions'!$L$35 -> 1.7668464 | S15: =S16*'Inputs & Assumptions'!$L$60/'Inputs & Assumptions'!$L$35 -> 1.6254987 | ... AY15: =AY16*'Inputs & Assumptions'!$L$60/'Inputs & Assumptions'!$L$35 -> 0
G16: Total MMcfe | J16: =SUM(L16:AO16) -> 15000 | L16: =MIN('Inputs & Assumptions'!$L$85,'Inputs & Assumptions'!$L$90*L12) -> 1875 | M16: =MIN(L16*(1-M17),'Inputs & Assumptions'!$L$85-SUM($L$16:L16)) -> 1200 | N16: =MIN(M16*(1-N17),'Inputs & Assumptions'!$L$85-SUM($L$16:M16)) -> 1008 | O16: =MIN(N16*(1-O17),'Inputs & Assumptions'!$L$85-SUM($L$16:N16)) -> 876.96 | P16: =MIN(O16*(1-P17),'Inputs & Assumptions'!$L$85-SUM($L$16:O16)) -> 789.264 | Q16: =MIN(P16*(1-Q17),'Inputs & Assumptions'!$L$85-SUM($L$16:P16)) -> 710.3376 | R16: =MIN(Q16*(1-R17),'Inputs & Assumptions'!$L$85-SUM($L$16:Q16)) -> 646.40722 | S16: =MIN(R16*(1-S17),'Inputs & Assumptions'!$L$85-SUM($L$16:R16)) -> 594.69464 | T16: =MIN(S16*(1-T17),'Inputs & Assumptions'!$L$85-SUM($L$16:S16)) -> 553.06601 | ... AY16: =MIN(AX16*(1-AY17),'Inputs & Assumptions'!$L$85-SUM($L$16:AX16)) -> 0
G17: Decline Rate | M17: 0.36 | N17: 0.16 | O17: 0.13 | P17: 0.1 | Q17: 0.1 | R17: 0.09 | S17: 0.08 | T17: 0.07 | U17: 0.06 | V17: 0.05 | W17: 0.05 | X17: 0.05 | Y17: 0.05 | Z17: 0.04 | AA17: 0.04 | AB17: 0.04 | AC17: 0.04 | AD17: 0.04 | AE17: 0.04 | AF17: 0.04 | AG17: 0.04 | AH17: 0.04 | AI17: 0.04 | AJ17: 0.04 | AK17: 0.04 | AL17: 0.04 | AM17: 0.04 | AN17: 0.04 | AO17: 0.04 | AP17: 0.04 | AQ17: 0.04 | AR17: 0.04 | AS17: 0.04 | AT17: 0.04 | AU17: 1.04 | AV17: 2.04 | AW17: 3.04 | AX17: 4.04 | AY17: 5.04
B19: 1. | C19: Annual PUD Depletion
G22: Period | L22: 1 | M22: 2 | N22: 3 | O22: 4 | P22: 5 | Q22: 6 | R22: 7 | S22: 8 | T22: 9 | U22: 10 | V22: 11 | W22: 12 | X22: 13 | Y22: 14 | Z22: 15 | AA22: 16 | AB22: 17 | AC22: 18 | AD22: 19 | AE22: 20 | AF22: 21 | AG22: 22 | AH22: 23 | AI22: 24 | AJ22: 25 | AK22: 26 | AL22: 27 | AM22: 28 | AN22: 29 | AO22: 30 | AP22: Total
G23: Net Wells Drilled | L23: 55 | M23: 55 | N23: 55 | O23: 55 | P23: 55 | Q23: 55 | R23: 55 | S23: 28.378867 | T23: 0 | U23: 0 | V23: 0 | W23: 0 | X23: 0 | Y23: 0 | Z23: 0 | AA23: 0 | AB23: 0 | AC23: 0 | AD23: 0 | AE23: 0 | AF23: 0 | AG23: 0 | AH23: 0 | AI23: 0 | AJ23: 0 | AK23: 0 | AL23: 0 | AM23: 0 | AN23: 0 | AO23: 0
G24: Total D&C costs | L24: =L23*'Inputs & Assumptions'!$L$92 -> 563.75 | M24: =M23*'Inputs & Assumptions'!$L$92 -> 563.75 | N24: =N23*'Inputs & Assumptions'!$L$92 -> 563.75 | O24: =O23*'Inputs & Assumptions'!$L$92 -> 563.75 | P24: =P23*'Inputs & Assumptions'!$L$92 -> 563.75 | Q24: =Q23*'Inputs & Assumptions'!$L$92 -> 563.75 | R24: =R23*'Inputs & Assumptions'!$L$92 -> 563.75 | S24: =S23*'Inputs & Assumptions'!$L$92 -> 290.88338 | ... AO24: =AO23*'Inputs & Assumptions'!$L$92 -> 0 | AP24: =SUM(L24:S24) -> 4237.1334
G27: PUD MMcfe per year | K27: Period | L27: =IF($K28<L$22,0,AVERAGE(OFFSET($I$16,,$K28-L$22+3)*L$23,OFFSET($I$16,0,$K28-L$22+2)*L$23)) -> 51562.5 | M27: =IF($K28<M$22,0,AVERAGE(OFFSET($I$16,,$K28-M$22+3)*M$23,OFFSET($I$16,0,$K28-M$22+2)*M$23)) -> 0 | N27: =IF($K28<N$22,0,AVERAGE(OFFSET($I$16,,$K28-N$22+3)*N$23,OFFSET($I$16,0,$K28-N$22+2)*N$23)) -> 0 | O27: =IF($K28<O$22,0,AVERAGE(OFFSET($I$16,,$K28-O$22+3)*O$23,OFFSET($I$16,0,$K28-O$22+2)*O$23)) -> 0 | P27: =IF($K28<P$22,0,AVERAGE(OFFSET($I$16,,$K28-P$22+3)*P$23,OFFSET($I$16,0,$K28-P$22+2)*P$23)) -> 0 | Q27: =IF($K28<Q$22,0,AVERAGE(OFFSET($I$16,,$K28-Q$22+3)*Q$23,OFFSET($I$16,0,$K28-Q$22+2)*Q$23)) -> 0 | R27: =IF($K28<R$22,0,AVERAGE(OFFSET($I$16,,$K28-R$22+3)*R$23,OFFSET($I$16,0,$K28-R$22+2)*R$23)) -> 0 | S27: =IF($K28<S$22,0,AVERAGE(OFFSET($I$16,,$K28-S$22+3)*S$23,OFFSET($I$16,0,$K28-S$22+2)*S$23)) -> 0 | ... AO27: =IF($K28<AO$22,0,AVERAGE(OFFSET($I$16,,$K28-AO$22+3)*AO$23,OFFSET($I$16,0,$K28-AO$22+2)*AO$23)) -> 0 | AP27: =SUM(L27:AI27) -> 51562.5
K28: 1 | L28: =IF($K29<L$22,0,AVERAGE(OFFSET($I$16,,$K29-L$22+3)*L$23,OFFSET($I$16,0,$K29-L$22+2)*L$23)) -> 84562.5 | M28: =IF($K29<M$22,0,AVERAGE(OFFSET($I$16,,$K29-M$22+3)*M$23,OFFSET($I$16,0,$K29-M$22+2)*M$23)) -> 51562.5 | N28: =IF($K29<N$22,0,AVERAGE(OFFSET($I$16,,$K29-N$22+3)*N$23,OFFSET($I$16,0,$K29-N$22+2)*N$23)) -> 0 | O28: =IF($K29<O$22,0,AVERAGE(OFFSET($I$16,,$K29-O$22+3)*O$23,OFFSET($I$16,0,$K29-O$22+2)*O$23)) -> 0 | P28: =IF($K29<P$22,0,AVERAGE(OFFSET($I$16,,$K29-P$22+3)*P$23,OFFSET($I$16,0,$K29-P$22+2)*P$23)) -> 0 | Q28: =IF($K29<Q$22,0,AVERAGE(OFFSET($I$16,,$K29-Q$22+3)*Q$23,OFFSET($I$16,0,$K29-Q$22+2)*Q$23)) -> 0 | R28: =IF($K29<R$22,0,AVERAGE(OFFSET($I$16,,$K29-R$22+3)*R$23,OFFSET($I$16,0,$K29-R$22+2)*R$23)) -> 0 | S28: =IF($K29<S$22,0,AVERAGE(OFFSET($I$16,,$K29-S$22+3)*S$23,OFFSET($I$16,0,$K29-S$22+2)*S$23)) -> 0 | ... AO28: =IF($K29<AO$22,0,AVERAGE(OFFSET($I$16,,$K29-AO$22+3)*AO$23,OFFSET($I$16,0,$K29-AO$22+2)*AO$23)) -> 0 | AP28: =SUM(L28:AI28) -> 136125
K29: 2 | L29: =IF($K30<L$22,0,AVERAGE(OFFSET($I$16,,$K30-L$22+3)*L$23,OFFSET($I$16,0,$K30-L$22+2)*L$23)) -> 60720 | M29: =IF($K30<M$22,0,AVERAGE(OFFSET($I$16,,$K30-M$22+3)*M$23,OFFSET($I$16,0,$K30-M$22+2)*M$23)) -> 84562.5 | N29: =IF($K30<N$22,0,AVERAGE(OFFSET($I$16,,$K30-N$22+3)*N$23,OFFSET($I$16,0,$K30-N$22+2)*N$23)) -> 51562.5 | O29: =IF($K30<O$22,0,AVERAGE(OFFSET($I$16,,$K30-O$22+3)*O$23,OFFSET($I$16,0,$K30-O$22+2)*O$23)) -> 0 | P29: =IF($K30<P$22,0,AVERAGE(OFFSET($I$16,,$K30-P$22+3)*P$23,OFFSET($I$16,0,$K30-P$22+2)*P$23)) -> 0 | Q29: =IF($K30<Q$22,0,AVERAGE(OFFSET($I$16,,$K30-Q$22+3)*Q$23,OFFSET($I$16,0,$K30-Q$22+2)*Q$23)) -> 0 | R29: =IF($K30<R$22,0,AVERAGE(OFFSET($I$16,,$K30-R$22+3)*R$23,OFFSET($I$16,0,$K30-R$22+2)*R$23)) -> 0 | S29: =IF($K30<S$22,0,AVERAGE(OFFSET($I$16,,$K30-S$22+3)*S$23,OFFSET($I$16,0,$K30-S$22+2)*S$23)) -> 0 | ... AO29: =IF($K30<AO$22,0,AVERAGE(OFFSET($I$16,,$K30-AO$22+3)*AO$23,OFFSET($I$16,0,$K30-AO$22+2)*AO$23)) -> 0 | AP29: =SUM(L29:AI29) -> 196845
K30: 3 | L30: =IF($K31<L$22,0,AVERAGE(OFFSET($I$16,,$K31-L$22+3)*L$23,OFFSET($I$16,0,$K31-L$22+2)*L$23)) -> 51836.4 | M30: =IF($K31<M$22,0,AVERAGE(OFFSET($I$16,,$K31-M$22+3)*M$23,OFFSET($I$16,0,$K31-M$22+2)*M$23)) -> 60720 | N30: =IF($K31<N$22,0,AVERAGE(OFFSET($I$16,,$K31-N$22+3)*N$23,OFFSET($I$16,0,$K31-N$22+2)*N$23)) -> 84562.5 | O30: =IF($K31<O$22,0,AVERAGE(OFFSET($I$16,,$K31-O$22+3)*O$23,OFFSET($I$16,0,$K31-O$22+2)*O$23)) -> 51562.5 | P30: =IF($K31<P$22,0,AVERAGE(OFFSET($I$16,,$K31-P$22+3)*P$23,OFFSET($I$16,0,$K31-P$22+2)*P$23)) -> 0 | Q30: =IF($K31<Q$22,0,AVERAGE(OFFSET($I$16,,$K31-Q$22+3)*Q$23,OFFSET($I$16,0,$K31-Q$22+2)*Q$23)) -> 0 | R30: =IF($K31<R$22,0,AVERAGE(OFFSET($I$16,,$K31-R$22+3)*R$23,OFFSET($I$16,0,$K31-R$22+2)*R$23)) -> 0 | S30: =IF($K31<S$22,0,AVERAGE(OFFSET($I$16,,$K31-S$22+3)*S$23,OFFSET($I$16,0,$K31-S$22+2)*S$23)) -> 0 | ... AO30: =IF($K31<AO$22,0,AVERAGE(OFFSET($I$16,,$K31-AO$22+3)*AO$23,OFFSET($I$16,0,$K31-AO$22+2)*AO$23)) -> 0 | AP30: =SUM(L30:AI30) -> 248681.4
K31: 4 | L31: =IF($K32<L$22,0,AVERAGE(OFFSET($I$16,,$K32-L$22+3)*L$23,OFFSET($I$16,0,$K32-L$22+2)*L$23)) -> 45821.16 | M31: =IF($K32<M$22,0,AVERAGE(OFFSET($I$16,,$K32-M$22+3)*M$23,OFFSET($I$16,0,$K32-M$22+2)*M$23)) -> 51836.4 | N31: =IF($K32<N$22,0,AVERAGE(OFFSET($I$16,,$K32-N$22+3)*N$23,OFFSET($I$16,0,$K32-N$22+2)*N$23)) -> 60720 | O31: =IF($K32<O$22,0,AVERAGE(OFFSET($I$16,,$K32-O$22+3)*O$23,OFFSET($I$16,0,$K32-O$22+2)*O$23)) -> 84562.5 | P31: =IF($K32<P$22,0,AVERAGE(OFFSET($I$16,,$K32-P$22+3)*P$23,OFFSET($I$16,0,$K32-P$22+2)*P$23)) -> 51562.5 | Q31: =IF($K32<Q$22,0,AVERAGE(OFFSET($I$16,,$K32-Q$22+3)*Q$23,OFFSET($I$16,0,$K32-Q$22+2)*Q$23)) -> 0 | R31: =IF($K32<R$22,0,AVERAGE(OFFSET($I$16,,$K32-R$22+3)*R$23,OFFSET($I$16,0,$K32-R$22+2)*R$23)) -> 0 | S31: =IF($K32<S$22,0,AVERAGE(OFFSET($I$16,,$K32-S$22+3)*S$23,OFFSET($I$16,0,$K32-S$22+2)*S$23)) -> 0 | ... AO31: =IF($K32<AO$22,0,AVERAGE(OFFSET($I$16,,$K32-AO$22+3)*AO$23,OFFSET($I$16,0,$K32-AO$22+2)*AO$23)) -> 0 | AP31: =SUM(L31:AI31) -> 294502.56
K32: 5 | L32: =IF($K33<L$22,0,AVERAGE(OFFSET($I$16,,$K33-L$22+3)*L$23,OFFSET($I$16,0,$K33-L$22+2)*L$23)) -> 41239.044 | M32: =IF($K33<M$22,0,AVERAGE(OFFSET($I$16,,$K33-M$22+3)*M$23,OFFSET($I$16,0,$K33-M$22+2)*M$23)) -> 45821.16 | N32: =IF($K33<N$22,0,AVERAGE(OFFSET($I$16,,$K33-N$22+3)*N$23,OFFSET($I$16,0,$K33-N$22+2)*N$23)) -> 51836.4 | O32: =IF($K33<O$22,0,AVERAGE(OFFSET($I$16,,$K33-O$22+3)*O$23,OFFSET($I$16,0,$K33-O$22+2)*O$23)) -> 60720 | P32: =IF($K33<P$22,0,AVERAGE(OFFSET($I$16,,$K33-P$22+3)*P$23,OFFSET($I$16,0,$K33-P$22+2)*P$23)) -> 84562.5 | Q32: =IF($K33<Q$22,0,AVERAGE(OFFSET($I$16,,$K33-Q$22+3)*Q$23,OFFSET($I$16,0,$K33-Q$22+2)*Q$23)) -> 51562.5 | R32: =IF($K33<R$22,0,AVERAGE(OFFSET($I$16,,$K33-R$22+3)*R$23,OFFSET($I$16,0,$K33-R$22+2)*R$23)) -> 0 | S32: =IF($K33<S$22,0,AVERAGE(OFFSET($I$16,,$K33-S$22+3)*S$23,OFFSET($I$16,0,$K33-S$22+2)*S$23)) -> 0 | ... AO32: =IF($K33<AO$22,0,AVERAGE(OFFSET($I$16,,$K33-AO$22+3)*AO$23,OFFSET($I$16,0,$K33-AO$22+2)*AO$23)) -> 0 | AP32: =SUM(L32:AI32) -> 335741.6
K33: 6 | L33: =IF($K34<L$22,0,AVERAGE(OFFSET($I$16,,$K34-L$22+3)*L$23,OFFSET($I$16,0,$K34-L$22+2)*L$23)) -> 37310.482 | M33: =IF($K34<M$22,0,AVERAGE(OFFSET($I$16,,$K34-M$22+3)*M$23,OFFSET($I$16,0,$K34-M$22+2)*M$23)) -> 41239.044 | N33: =IF($K34<N$22,0,AVERAGE(OFFSET($I$16,,$K34-N$22+3)*N$23,OFFSET($I$16,0,$K34-N$22+2)*N$23)) -> 45821.16 | O33: =IF($K34<O$22,0,AVERAGE(OFFSET($I$16,,$K34-O$22+3)*O$23,OFFSET($I$16,0,$K34-O$22+2)*O$23)) -> 51836.4 | P33: =IF($K34<P$22,0,AVERAGE(OFFSET($I$16,,$K34-P$22+3)*P$23,OFFSET($I$16,0,$K34-P$22+2)*P$23)) -> 60720 | Q33: =IF($K34<Q$22,0,AVERAGE(OFFSET($I$16,,$K34-Q$22+3)*Q$23,OFFSET($I$16,0,$K34-Q$22+2)*Q$23)) -> 84562.5 | R33: =IF($K34<R$22,0,AVERAGE(OFFSET($I$16,,$K34-R$22+3)*R$23,OFFSET($I$16,0,$K34-R$22+2)*R$23)) -> 51562.5 | S33: =IF($K34<S$22,0,AVERAGE(OFFSET($I$16,,$K34-S$22+3)*S$23,OFFSET($I$16,0,$K34-S$22+2)*S$23)) -> 0 | ... AO33: =IF($K34<AO$22,0,AVERAGE(OFFSET($I$16,,$K34-AO$22+3)*AO$23,OFFSET($I$16,0,$K34-AO$22+2)*AO$23)) -> 0 | AP33: =SUM(L33:AI33) -> 373052.09
K34: 7 | L34: =IF($K35<L$22,0,AVERAGE(OFFSET($I$16,,$K35-L$22+3)*L$23,OFFSET($I$16,0,$K35-L$22+2)*L$23)) -> 34130.301 | M34: =IF($K35<M$22,0,AVERAGE(OFFSET($I$16,,$K35-M$22+3)*M$23,OFFSET($I$16,0,$K35-M$22+2)*M$23)) -> 37310.482 | N34: =IF($K35<N$22,0,AVERAGE(OFFSET($I$16,,$K35-N$22+3)*N$23,OFFSET($I$16,0,$K35-N$22+2)*N$23)) -> 41239.044 | O34: =IF($K35<O$22,0,AVERAGE(OFFSET($I$16,,$K35-O$22+3)*O$23,OFFSET($I$16,0,$K35-O$22+2)*O$23)) -> 45821.16 | P34: =IF($K35<P$22,0,AVERAGE(OFFSET($I$16,,$K35-P$22+3)*P$23,OFFSET($I$16,0,$K35-P$22+2)*P$23)) -> 51836.4 | Q34: =IF($K35<Q$22,0,AVERAGE(OFFSET($I$16,,$K35-Q$22+3)*Q$23,OFFSET($I$16,0,$K35-Q$22+2)*Q$23)) -> 60720 | R34: =IF($K35<R$22,0,AVERAGE(OFFSET($I$16,,$K35-R$22+3)*R$23,OFFSET($I$16,0,$K35-R$22+2)*R$23)) -> 84562.5 | S34: =IF($K35<S$22,0,AVERAGE(OFFSET($I$16,,$K35-S$22+3)*S$23,OFFSET($I$16,0,$K35-S$22+2)*S$23)) -> 26605.188 | ... AO34: =IF($K35<AO$22,0,AVERAGE(OFFSET($I$16,,$K35-AO$22+3)*AO$23,OFFSET($I$16,0,$K35-AO$22+2)*AO$23)) -> 0 | AP34: =SUM(L34:AI34) -> 382225.07
K35: 8 | L35: =IF($K36<L$22,0,AVERAGE(OFFSET($I$16,,$K36-L$22+3)*L$23,OFFSET($I$16,0,$K36-L$22+2)*L$23)) -> 31563.418 | M35: =IF($K36<M$22,0,AVERAGE(OFFSET($I$16,,$K36-M$22+3)*M$23,OFFSET($I$16,0,$K36-M$22+2)*M$23)) -> 34130.301 | N35: =IF($K36<N$22,0,AVERAGE(OFFSET($I$16,,$K36-N$22+3)*N$23,OFFSET($I$16,0,$K36-N$22+2)*N$23)) -> 37310.482 | O35: =IF($K36<O$22,0,AVERAGE(OFFSET($I$16,,$K36-O$22+3)*O$23,OFFSET($I$16,0,$K36-O$22+2)*O$23)) -> 41239.044 | P35: =IF($K36<P$22,0,AVERAGE(OFFSET($I$16,,$K36-P$22+3)*P$23,OFFSET($I$16,0,$K36-P$22+2)*P$23)) -> 45821.16 | Q35: =IF($K36<Q$22,0,AVERAGE(OFFSET($I$16,,$K36-Q$22+3)*Q$23,OFFSET($I$16,0,$K36-Q$22+2)*Q$23)) -> 51836.4 | R35: =IF($K36<R$22,0,AVERAGE(OFFSET($I$16,,$K36-R$22+3)*R$23,OFFSET($I$16,0,$K36-R$22+2)*R$23)) -> 60720 | S35: =IF($K36<S$22,0,AVERAGE(OFFSET($I$16,,$K36-S$22+3)*S$23,OFFSET($I$16,0,$K36-S$22+2)*S$23)) -> 43632.508 | ... AO35: =IF($K36<AO$22,0,AVERAGE(OFFSET($I$16,,$K36-AO$22+3)*AO$23,OFFSET($I$16,0,$K36-AO$22+2)*AO$23)) -> 0 | AP35: =SUM(L35:AI35) -> 346253.31
K36: 9 | L36: =IF($K37<L$22,0,AVERAGE(OFFSET($I$16,,$K37-L$22+3)*L$23,OFFSET($I$16,0,$K37-L$22+2)*L$23)) -> 29506.072 | M36: =IF($K37<M$22,0,AVERAGE(OFFSET($I$16,,$K37-M$22+3)*M$23,OFFSET($I$16,0,$K37-M$22+2)*M$23)) -> 31563.418 | N36: =IF($K37<N$22,0,AVERAGE(OFFSET($I$16,,$K37-N$22+3)*N$23,OFFSET($I$16,0,$K37-N$22+2)*N$23)) -> 34130.301 | O36: =IF($K37<O$22,0,AVERAGE(OFFSET($I$16,,$K37-O$22+3)*O$23,OFFSET($I$16,0,$K37-O$22+2)*O$23)) -> 37310.482 | P36: =IF($K37<P$22,0,AVERAGE(OFFSET($I$16,,$K37-P$22+3)*P$23,OFFSET($I$16,0,$K37-P$22+2)*P$23)) -> 41239.044 | Q36: =IF($K37<Q$22,0,AVERAGE(OFFSET($I$16,,$K37-Q$22+3)*Q$23,OFFSET($I$16,0,$K37-Q$22+2)*Q$23)) -> 45821.16 | R36: =IF($K37<R$22,0,AVERAGE(OFFSET($I$16,,$K37-R$22+3)*R$23,OFFSET($I$16,0,$K37-R$22+2)*R$23)) -> 51836.4 | S36: =IF($K37<S$22,0,AVERAGE(OFFSET($I$16,,$K37-S$22+3)*S$23,OFFSET($I$16,0,$K37-S$22+2)*S$23)) -> 31330.269 | ... AO36: =IF($K37<AO$22,0,AVERAGE(OFFSET($I$16,,$K37-AO$22+3)*AO$23,OFFSET($I$16,0,$K37-AO$22+2)*AO$23)) -> 0 | AP36: =SUM(L36:AI36) -> 302737.15
K37: 10 | L37: =IF($K38<L$22,0,AVERAGE(OFFSET($I$16,,$K38-L$22+3)*L$23,OFFSET($I$16,0,$K38-L$22+2)*L$23)) -> 27878.675 | M37: =IF($K38<M$22,0,AVERAGE(OFFSET($I$16,,$K38-M$22+3)*M$23,OFFSET($I$16,0,$K38-M$22+2)*M$23)) -> 29506.072 | N37: =IF($K38<N$22,0,AVERAGE(OFFSET($I$16,,$K38-N$22+3)*N$23,OFFSET($I$16,0,$K38-N$22+2)*N$23)) -> 31563.418 | O37: =IF($K38<O$22,0,AVERAGE(OFFSET($I$16,,$K38-O$22+3)*O$23,OFFSET($I$16,0,$K38-O$22+2)*O$23)) -> 34130.301 | P37: =IF($K38<P$22,0,AVERAGE(OFFSET($I$16,,$K38-P$22+3)*P$23,OFFSET($I$16,0,$K38-P$22+2)*P$23)) -> 37310.482 | Q37: =IF($K38<Q$22,0,AVERAGE(OFFSET($I$16,,$K38-Q$22+3)*Q$23,OFFSET($I$16,0,$K38-Q$22+2)*Q$23)) -> 41239.044 | R37: =IF($K38<R$22,0,AVERAGE(OFFSET($I$16,,$K38-R$22+3)*R$23,OFFSET($I$16,0,$K38-R$22+2)*R$23)) -> 45821.16 | S37: =IF($K38<S$22,0,AVERAGE(OFFSET($I$16,,$K38-S$22+3)*S$23,OFFSET($I$16,0,$K38-S$22+2)*S$23)) -> 26746.514 | ... AO37: =IF($K38<AO$22,0,AVERAGE(OFFSET($I$16,,$K38-AO$22+3)*AO$23,OFFSET($I$16,0,$K38-AO$22+2)*AO$23)) -> 0 | AP37: =SUM(L37:AI37) -> 274195.67
K38: 11 | L38: =IF($K39<L$22,0,AVERAGE(OFFSET($I$16,,$K39-L$22+3)*L$23,OFFSET($I$16,0,$K39-L$22+2)*L$23)) -> 26484.741 | M38: =IF($K39<M$22,0,AVERAGE(OFFSET($I$16,,$K39-M$22+3)*M$23,OFFSET($I$16,0,$K39-M$22+2)*M$23)) -> 27878.675 | N38: =IF($K39<N$22,0,AVERAGE(OFFSET($I$16,,$K39-N$22+3)*N$23,OFFSET($I$16,0,$K39-N$22+2)*N$23)) -> 29506.072 | O38: =IF($K39<O$22,0,AVERAGE(OFFSET($I$16,,$K39-O$22+3)*O$23,OFFSET($I$16,0,$K39-O$22+2)*O$23)) -> 31563.418 | P38: =IF($K39<P$22,0,AVERAGE(OFFSET($I$16,,$K39-P$22+3)*P$23,OFFSET($I$16,0,$K39-P$22+2)*P$23)) -> 34130.301 | Q38: =IF($K39<Q$22,0,AVERAGE(OFFSET($I$16,,$K39-Q$22+3)*Q$23,OFFSET($I$16,0,$K39-Q$22+2)*Q$23)) -> 37310.482 | R38: =IF($K39<R$22,0,AVERAGE(OFFSET($I$16,,$K39-R$22+3)*R$23,OFFSET($I$16,0,$K39-R$22+2)*R$23)) -> 41239.044 | S38: =IF($K39<S$22,0,AVERAGE(OFFSET($I$16,,$K39-S$22+3)*S$23,OFFSET($I$16,0,$K39-S$22+2)*S$23)) -> 23642.774 | ... AO38: =IF($K39<AO$22,0,AVERAGE(OFFSET($I$16,,$K39-AO$22+3)*AO$23,OFFSET($I$16,0,$K39-AO$22+2)*AO$23)) -> 0 | AP38: =SUM(L38:AI38) -> 251755.51
K39: 12 | L39: =IF($K40<L$22,0,AVERAGE(OFFSET($I$16,,$K40-L$22+3)*L$23,OFFSET($I$16,0,$K40-L$22+2)*L$23)) -> 25160.504 | M39: =IF($K40<M$22,0,AVERAGE(OFFSET($I$16,,$K40-M$22+3)*M$23,OFFSET($I$16,0,$K40-M$22+2)*M$23)) -> 26484.741 | N39: =IF($K40<N$22,0,AVERAGE(OFFSET($I$16,,$K40-N$22+3)*N$23,OFFSET($I$16,0,$K40-N$22+2)*N$23)) -> 27878.675 | O39: =IF($K40<O$22,0,AVERAGE(OFFSET($I$16,,$K40-O$22+3)*O$23,OFFSET($I$16,0,$K40-O$22+2)*O$23)) -> 29506.072 | P39: =IF($K40<P$22,0,AVERAGE(OFFSET($I$16,,$K40-P$22+3)*P$23,OFFSET($I$16,0,$K40-P$22+2)*P$23)) -> 31563.418 | Q39: =IF($K40<Q$22,0,AVERAGE(OFFSET($I$16,,$K40-Q$22+3)*Q$23,OFFSET($I$16,0,$K40-Q$22+2)*Q$23)) -> 34130.301 | R39: =IF($K40<R$22,0,AVERAGE(OFFSET($I$16,,$K40-R$22+3)*R$23,OFFSET($I$16,0,$K40-R$22+2)*R$23)) -> 37310.482 | S39: =IF($K40<S$22,0,AVERAGE(OFFSET($I$16,,$K40-S$22+3)*S$23,OFFSET($I$16,0,$K40-S$22+2)*S$23)) -> 21278.497 | ... AO39: =IF($K40<AO$22,0,AVERAGE(OFFSET($I$16,,$K40-AO$22+3)*AO$23,OFFSET($I$16,0,$K40-AO$22+2)*AO$23)) -> 0 | AP39: =SUM(L39:AI39) -> 233312.69
... K58: 31 | L58: =IF($K59<L$22,0,AVERAGE(OFFSET($I$16,,$K59-L$22+3)*L$23,OFFSET($I$16,0,$K59-L$22+2)*L$23)) -> 0 | M58: =IF($K59<M$22,0,AVERAGE(OFFSET($I$16,,$K59-M$22+3)*M$23,OFFSET($I$16,0,$K59-M$22+2)*M$23)) -> 0 | N58: =IF($K59<N$22,0,AVERAGE(OFFSET($I$16,,$K59-N$22+3)*N$23,OFFSET($I$16,0,$K59-N$22+2)*N$23)) -> 0 | O58: =IF($K59<O$22,0,AVERAGE(OFFSET($I$16,,$K59-O$22+3)*O$23,OFFSET($I$16,0,$K59-O$22+2)*O$23)) -> 5750.9822 | P58: =IF($K59<P$22,0,AVERAGE(OFFSET($I$16,,$K59-P$22+3)*P$23,OFFSET($I$16,0,$K59-P$22+2)*P$23)) -> 12600.468 | Q58: =IF($K59<Q$22,0,AVERAGE(OFFSET($I$16,,$K59-Q$22+3)*Q$23,OFFSET($I$16,0,$K59-Q$22+2)*Q$23)) -> 13984.367 | R58: =IF($K59<R$22,0,AVERAGE(OFFSET($I$16,,$K59-R$22+3)*R$23,OFFSET($I$16,0,$K59-R$22+2)*R$23)) -> 14567.049 | S58: =IF($K59<S$22,0,AVERAGE(OFFSET($I$16,,$K59-S$22+3)*S$23,OFFSET($I$16,0,$K59-S$22+2)*S$23)) -> 7829.4761 | ... AO58: =IF($K59<AO$22,0,AVERAGE(OFFSET($I$16,,$K59-AO$22+3)*AO$23,OFFSET($I$16,0,$K59-AO$22+2)*AO$23)) -> 0 | AP58: =SUM(L58:AI58) -> 54732.342
K59: 32 | L59: =IF($K60<L$22,0,AVERAGE(OFFSET($I$16,,$K60-L$22+3)*L$23,OFFSET($I$16,0,$K60-L$22+2)*L$23)) -> 0 | M59: =IF($K60<M$22,0,AVERAGE(OFFSET($I$16,,$K60-M$22+3)*M$23,OFFSET($I$16,0,$K60-M$22+2)*M$23)) -> 0 | N59: =IF($K60<N$22,0,AVERAGE(OFFSET($I$16,,$K60-N$22+3)*N$23,OFFSET($I$16,0,$K60-N$22+2)*N$23)) -> 0 | O59: =IF($K60<O$22,0,AVERAGE(OFFSET($I$16,,$K60-O$22+3)*O$23,OFFSET($I$16,0,$K60-O$22+2)*O$23)) -> 0 | P59: =IF($K60<P$22,0,AVERAGE(OFFSET($I$16,,$K60-P$22+3)*P$23,OFFSET($I$16,0,$K60-P$22+2)*P$23)) -> 5750.9822 | Q59: =IF($K60<Q$22,0,AVERAGE(OFFSET($I$16,,$K60-Q$22+3)*Q$23,OFFSET($I$16,0,$K60-Q$22+2)*Q$23)) -> 12600.468 | R59: =IF($K60<R$22,0,AVERAGE(OFFSET($I$16,,$K60-R$22+3)*R$23,OFFSET($I$16,0,$K60-R$22+2)*R$23)) -> 13984.367 | S59: =IF($K60<S$22,0,AVERAGE(OFFSET($I$16,,$K60-S$22+3)*S$23,OFFSET($I$16,0,$K60-S$22+2)*S$23)) -> 7516.297 | ... V59: =IF($K60<V$22,0,AVERAGE(OFFSET($I$16,,$K60-V$22+3)*V$23,OFFSET($I$16,0,$K60-V$22+2)*V$23)) -> 0 | W59: =IF($F60<W$22,0,AVERAGE(OFFSET($I$16,,$F60-W$22+3)*W$23,OFFSET($I$16,0,$F60-W$22+2)*W$23)) -> 0 | X59: =IF($F60<X$22,0,AVERAGE(OFFSET($I$16,,$F60-X$22+3)*X$23,OFFSET($I$16,0,$F60-X$22+2)*X$23)) -> 0 | Y59: =IF($F60<Y$22,0,AVERAGE(OFFSET($I$16,,$F60-Y$22+3)*Y$23,OFFSET($I$16,0,$F60-Y$22+2)*Y$23)) -> 0 | Z59: =IF($F60<Z$22,0,AVERAGE(OFFSET($I$16,,$F60-Z$22+3)*Z$23,OFFSET($I$16,0,$F60-Z$22+2)*Z$23)) -> 0 | AA59: =IF($F60<AA$22,0,AVERAGE(OFFSET($I$16,,$F60-AA$22+3)*AA$23,OFFSET($I$16,0,$F60-AA$22+2)*AA$23)) -> 0 | AB59: =IF($F60<AB$22,0,AVERAGE(OFFSET($I$16,,$F60-AB$22+3)*AB$23,OFFSET($I$16,0,$F60-AB$22+2)*AB$23)) -> 0 | AC59: =IF($F60<AC$22,0,AVERAGE(OFFSET($I$16,,$F60-AC$22+3)*AC$23,OFFSET($I$16,0,$F60-AC$22+2)*AC$23)) -> 0 | AD59: =IF($F60<AD$22,0,AVERAGE(OFFSET($I$16,,$F60-AD$22+3)*AD$23,OFFSET($I$16,0,$F60-AD$22+2)*AD$23)) -> 0 | ... AO59: =IF($F60<AO$22,0,AVERAGE(OFFSET($I$16,,$F60-AO$22+3)*AO$23,OFFSET($I$16,0,$F60-AO$22+2)*AO$23)) -> 0 | AP59: =SUM(L59:AI59) -> 39852.114
K60: 33 | L60: =IF($K61<L$22,0,AVERAGE(OFFSET($I$16,,$K61-L$22+3)*L$23,OFFSET($I$16,0,$K61-L$22+2)*L$23)) -> 0 | M60: =IF($K61<M$22,0,AVERAGE(OFFSET($I$16,,$K61-M$22+3)*M$23,OFFSET($I$16,0,$K61-M$22+2)*M$23)) -> 0 | N60: =IF($K61<N$22,0,AVERAGE(OFFSET($I$16,,$K61-N$22+3)*N$23,OFFSET($I$16,0,$K61-N$22+2)*N$23)) -> 0 | O60: =IF($K61<O$22,0,AVERAGE(OFFSET($I$16,,$K61-O$22+3)*O$23,OFFSET($I$16,0,$K61-O$22+2)*O$23)) -> 0 | P60: =IF($K61<P$22,0,AVERAGE(OFFSET($I$16,,$K61-P$22+3)*P$23,OFFSET($I$16,0,$K61-P$22+2)*P$23)) -> 0 | Q60: =IF($K61<Q$22,0,AVERAGE(OFFSET($I$16,,$K61-Q$22+3)*Q$23,OFFSET($I$16,0,$K61-Q$22+2)*Q$23)) -> 5750.9822 | R60: =IF($K61<R$22,0,AVERAGE(OFFSET($I$16,,$K61-R$22+3)*R$23,OFFSET($I$16,0,$K61-R$22+2)*R$23)) -> 12600.468 | S60: =IF($K61<S$22,0,AVERAGE(OFFSET($I$16,,$K61-S$22+3)*S$23,OFFSET($I$16,0,$K61-S$22+2)*S$23)) -> 7215.6451 | ... V60: =IF($K61<V$22,0,AVERAGE(OFFSET($I$16,,$K61-V$22+3)*V$23,OFFSET($I$16,0,$K61-V$22+2)*V$23)) -> 0 | W60: =IF($F61<W$22,0,AVERAGE(OFFSET($I$16,,$F61-W$22+3)*W$23,OFFSET($I$16,0,$F61-W$22+2)*W$23)) -> 0 | X60: =IF($F61<X$22,0,AVERAGE(OFFSET($I$16,,$F61-X$22+3)*X$23,OFFSET($I$16,0,$F61-X$22+2)*X$23)) -> 0 | Y60: =IF($F61<Y$22,0,AVERAGE(OFFSET($I$16,,$F61-Y$22+3)*Y$23,OFFSET($I$16,0,$F61-Y$22+2)*Y$23)) -> 0 | Z60: =IF($F61<Z$22,0,AVERAGE(OFFSET($I$16,,$F61-Z$22+3)*Z$23,OFFSET($I$16,0,$F61-Z$22+2)*Z$23)) -> 0 | AA60: =IF($F61<AA$22,0,AVERAGE(OFFSET($I$16,,$F61-AA$22+3)*AA$23,OFFSET($I$16,0,$F61-AA$22+2)*AA$23)) -> 0 | AB60: =IF($F61<AB$22,0,AVERAGE(OFFSET($I$16,,$F61-AB$22+3)*AB$23,OFFSET($I$16,0,$F61-AB$22+2)*AB$23)) -> 0 | AC60: =IF($F61<AC$22,0,AVERAGE(OFFSET($I$16,,$F61-AC$22+3)*AC$23,OFFSET($I$16,0,$F61-AC$22+2)*AC$23)) -> 0 | AD60: =IF($F61<AD$22,0,AVERAGE(OFFSET($I$16,,$F61-AD$22+3)*AD$23,OFFSET($I$16,0,$F61-AD$22+2)*AD$23)) -> 0 | ... AO60: =IF($F61<AO$22,0,AVERAGE(OFFSET($I$16,,$F61-AO$22+3)*AO$23,OFFSET($I$16,0,$F61-AO$22+2)*AO$23)) -> 0 | AP60: =SUM(L60:AI60) -> 25567.095
K61: 34 | L61: =IF($K62<L$22,0,AVERAGE(OFFSET($I$16,,$K62-L$22+3)*L$23,OFFSET($I$16,0,$K62-L$22+2)*L$23)) -> 0 | M61: =IF($K62<M$22,0,AVERAGE(OFFSET($I$16,,$K62-M$22+3)*M$23,OFFSET($I$16,0,$K62-M$22+2)*M$23)) -> 0 | N61: =IF($K62<N$22,0,AVERAGE(OFFSET($I$16,,$K62-N$22+3)*N$23,OFFSET($I$16,0,$K62-N$22+2)*N$23)) -> 0 | O61: =IF($K62<O$22,0,AVERAGE(OFFSET($I$16,,$K62-O$22+3)*O$23,OFFSET($I$16,0,$K62-O$22+2)*O$23)) -> 0 | P61: =IF($K62<P$22,0,AVERAGE(OFFSET($I$16,,$K62-P$22+3)*P$23,OFFSET($I$16,0,$K62-P$22+2)*P$23)) -> 0 | Q61: =IF($K62<Q$22,0,AVERAGE(OFFSET($I$16,,$K62-Q$22+3)*Q$23,OFFSET($I$16,0,$K62-Q$22+2)*Q$23)) -> 0 | R61: =IF($K62<R$22,0,AVERAGE(OFFSET($I$16,,$K62-R$22+3)*R$23,OFFSET($I$16,0,$K62-R$22+2)*R$23)) -> 5750.9822 | S61: =IF($K62<S$22,0,AVERAGE(OFFSET($I$16,,$K62-S$22+3)*S$23,OFFSET($I$16,0,$K62-S$22+2)*S$23)) -> 6501.5818 | ... V61: =IF($K62<V$22,0,AVERAGE(OFFSET($I$16,,$K62-V$22+3)*V$23,OFFSET($I$16,0,$K62-V$22+2)*V$23)) -> 0 | W61: =IF($F62<W$22,0,AVERAGE(OFFSET($I$16,,$F62-W$22+3)*W$23,OFFSET($I$16,0,$F62-W$22+2)*W$23)) -> 0 | X61: =IF($F62<X$22,0,AVERAGE(OFFSET($I$16,,$F62-X$22+3)*X$23,OFFSET($I$16,0,$F62-X$22+2)*X$23)) -> 0 | Y61: =IF($F62<Y$22,0,AVERAGE(OFFSET($I$16,,$F62-Y$22+3)*Y$23,OFFSET($I$16,0,$F62-Y$22+2)*Y$23)) -> 0 | Z61: =IF($F62<Z$22,0,AVERAGE(OFFSET($I$16,,$F62-Z$22+3)*Z$23,OFFSET($I$16,0,$F62-Z$22+2)*Z$23)) -> 0 | AA61: =IF($F62<AA$22,0,AVERAGE(OFFSET($I$16,,$F62-AA$22+3)*AA$23,OFFSET($I$16,0,$F62-AA$22+2)*AA$23)) -> 0 | AB61: =IF($F62<AB$22,0,AVERAGE(OFFSET($I$16,,$F62-AB$22+3)*AB$23,OFFSET($I$16,0,$F62-AB$22+2)*AB$23)) -> 0 | AC61: =IF($F62<AC$22,0,AVERAGE(OFFSET($I$16,,$F62-AC$22+3)*AC$23,OFFSET($I$16,0,$F62-AC$22+2)*AC$23)) -> 0 | AD61: =IF($F62<AD$22,0,AVERAGE(OFFSET($I$16,,$F62-AD$22+3)*AD$23,OFFSET($I$16,0,$F62-AD$22+2)*AD$23)) -> 0 | ... AO61: =IF($F62<AO$22,0,AVERAGE(OFFSET($I$16,,$F62-AO$22+3)*AO$23,OFFSET($I$16,0,$F62-AO$22+2)*AO$23)) -> 0 | AP61: =SUM(L61:AI61) -> 12252.564
K62: 35 | L62: =IF($K63<L$22,0,AVERAGE(OFFSET($I$16,,$K63-L$22+3)*L$23,OFFSET($I$16,0,$K63-L$22+2)*L$23)) -> 0 | M62: =IF($K63<M$22,0,AVERAGE(OFFSET($I$16,,$K63-M$22+3)*M$23,OFFSET($I$16,0,$K63-M$22+2)*M$23)) -> 0 | N62: =IF($K63<N$22,0,AVERAGE(OFFSET($I$16,,$K63-N$22+3)*N$23,OFFSET($I$16,0,$K63-N$22+2)*N$23)) -> 0 | O62: =IF($K63<O$22,0,AVERAGE(OFFSET($I$16,,$K63-O$22+3)*O$23,OFFSET($I$16,0,$K63-O$22+2)*O$23)) -> 0 | P62: =IF($K63<P$22,0,AVERAGE(OFFSET($I$16,,$K63-P$22+3)*P$23,OFFSET($I$16,0,$K63-P$22+2)*P$23)) -> 0 | Q62: =IF($K63<Q$22,0,AVERAGE(OFFSET($I$16,,$K63-Q$22+3)*Q$23,OFFSET($I$16,0,$K63-Q$22+2)*Q$23)) -> 0 | R62: =IF($K63<R$22,0,AVERAGE(OFFSET($I$16,,$K63-R$22+3)*R$23,OFFSET($I$16,0,$K63-R$22+2)*R$23)) -> 0 | S62: =IF($K63<S$22,0,AVERAGE(OFFSET($I$16,,$K63-S$22+3)*S$23,OFFSET($I$16,0,$K63-S$22+2)*S$23)) -> 2967.3883 | ... V62: =IF($K63<V$22,0,AVERAGE(OFFSET($I$16,,$K63-V$22+3)*V$23,OFFSET($I$16,0,$K63-V$22+2)*V$23)) -> 0 | W62: =IF($F63<W$22,0,AVERAGE(OFFSET($I$16,,$F63-W$22+3)*W$23,OFFSET($I$16,0,$F63-W$22+2)*W$23)) -> 0 | X62: =IF($F63<X$22,0,AVERAGE(OFFSET($I$16,,$F63-X$22+3)*X$23,OFFSET($I$16,0,$F63-X$22+2)*X$23)) -> 0 | Y62: =IF($F63<Y$22,0,AVERAGE(OFFSET($I$16,,$F63-Y$22+3)*Y$23,OFFSET($I$16,0,$F63-Y$22+2)*Y$23)) -> 0 | Z62: =IF($F63<Z$22,0,AVERAGE(OFFSET($I$16,,$F63-Z$22+3)*Z$23,OFFSET($I$16,0,$F63-Z$22+2)*Z$23)) -> 0 | AA62: =IF($F63<AA$22,0,AVERAGE(OFFSET($I$16,,$F63-AA$22+3)*AA$23,OFFSET($I$16,0,$F63-AA$22+2)*AA$23)) -> 0 | AB62: =IF($F63<AB$22,0,AVERAGE(OFFSET($I$16,,$F63-AB$22+3)*AB$23,OFFSET($I$16,0,$F63-AB$22+2)*AB$23)) -> 0 | AC62: =IF($F63<AC$22,0,AVERAGE(OFFSET($I$16,,$F63-AC$22+3)*AC$23,OFFSET($I$16,0,$F63-AC$22+2)*AC$23)) -> 0 | AD62: =IF($F63<AD$22,0,AVERAGE(OFFSET($I$16,,$F63-AD$22+3)*AD$23,OFFSET($I$16,0,$F63-AD$22+2)*AD$23)) -> 0 | ... AO62: =IF($F63<AO$22,0,AVERAGE(OFFSET($I$16,,$F63-AO$22+3)*AO$23,OFFSET($I$16,0,$F63-AO$22+2)*AO$23)) -> 0 | AP62: =SUM(L62:AI62) -> 2967.3883
